<robot name = "robot">
    <link name="Start">
        <inertial>
            <origin xyz="0 0 0" rpy="0 0 0"/>
            <mass value="1" />
            <inertia ixx="100" ixy="0" ixz="0" iyy="100" iyz="0" izz="100" />
        </inertial>
        <visual>
            <origin xyz="0 0 0" rpy="0 0 0"/>
            <geometry>
                <box size="1 1 1" />
            </geometry>
            <material name="Green">
                <color rgba="0 1.0 0 1.0"/>
            </material>
        </visual>
        <collision>
            <origin xyz="0 0 0" rpy="0 0 0"/>
            <geometry>
                <box size="1 1 1" />
            </geometry>
        </collision>
    </link>
    <link name="Link1">
        <inertial>
            <origin xyz="0.842272760640316 0 0" rpy="0 0 0"/>
            <mass value="1" />
            <inertia ixx="100" ixy="0" ixz="0" iyy="100" iyz="0" izz="100" />
        </inertial>
        <visual>
            <origin xyz="0.842272760640316 0 0" rpy="0 0 0"/>
            <geometry>
                <box size="0.8791403141871548 1.898445731290036 0.30869267703035286" />
            </geometry>
            <material name="Green">
                <color rgba="0 1.0 0 1.0"/>
            </material>
        </visual>
        <collision>
            <origin xyz="0.842272760640316 0 0" rpy="0 0 0"/>
            <geometry>
                <box size="0.8791403141871548 1.898445731290036 0.30869267703035286" />
            </geometry>
        </collision>
    </link>
    <link name="Link2">
        <inertial>
            <origin xyz="-0.42612122017291665 0 0" rpy="0 0 0"/>
            <mass value="1" />
            <inertia ixx="100" ixy="0" ixz="0" iyy="100" iyz="0" izz="100" />
        </inertial>
        <visual>
            <origin xyz="-0.42612122017291665 0 0" rpy="0 0 0"/>
            <geometry>
                <box size="0.8522424403458333 0.5093857858263183 1.410977794544375" />
            </geometry>
            <material name="Green">
                <color rgba="0 1.0 0 1.0"/>
            </material>
        </visual>
        <collision>
            <origin xyz="-0.42612122017291665 0 0" rpy="0 0 0"/>
            <geometry>
                <box size="0.8522424403458333 0.5093857858263183 1.410977794544375" />
            </geometry>
        </collision>
    </link>
    <link name="Link3">
        <inertial>
            <origin xyz="0 0 0.42047414235507696" rpy="0 0 0"/>
            <mass value="1" />
            <inertia ixx="100" ixy="0" ixz="0" iyy="100" iyz="0" izz="100" />
        </inertial>
        <visual>
            <origin xyz="0 0 0.42047414235507696" rpy="0 0 0"/>
            <geometry>
                <box size="1.7418748710772847 0.584689917960053 0.930956304227563" />
            </geometry>
            <material name="Green">
                <color rgba="0 1.0 0 1.0"/>
            </material>
        </visual>
        <collision>
            <origin xyz="0 0 0.42047414235507696" rpy="0 0 0"/>
            <geometry>
                <box size="1.7418748710772847 0.584689917960053 0.930956304227563" />
            </geometry>
        </collision>
    </link>
    <link name="Link4">
        <inertial>
            <origin xyz="0 0 0.19120896088240436" rpy="0 0 0"/>
            <mass value="1" />
            <inertia ixx="100" ixy="0" ixz="0" iyy="100" iyz="0" izz="100" />
        </inertial>
        <visual>
            <origin xyz="0 0 0.19120896088240436" rpy="0 0 0"/>
            <geometry>
                <box size="1.2661733230389116 0.5709066109248188 0.3824179217648087" />
            </geometry>
            <material name="Green">
                <color rgba="0 1.0 0 1.0"/>
            </material>
        </visual>
        <collision>
            <origin xyz="0 0 0.19120896088240436" rpy="0 0 0"/>
            <geometry>
                <box size="1.2661733230389116 0.5709066109248188 0.3824179217648087" />
            </geometry>
        </collision>
    </link>
    <joint name="Start_Link1" type="revolute">
       <parent link="Start"/>
       <child  link="Link1"/>
       <origin rpy="0 0 0" xyz="0.5 0 0" />
     <axis xyz="1 0 0"/>
       <limit effort="0.0" lower="-3.14159" upper="3.14159" velocity="0.0"/>
    </joint>
    <joint name="Start_Link2" type="revolute">
       <parent link="Start"/>
       <child  link="Link2"/>
       <origin rpy="0 0 0" xyz="-0.5 0 0" />
     <axis xyz="1 0 0"/>
       <limit effort="0.0" lower="-3.14159" upper="3.14159" velocity="0.0"/>
    </joint>
    <joint name="Link1_Link3" type="revolute">
       <parent link="Link1"/>
       <child  link="Link3"/>
       <origin rpy="0 0 0" xyz="0.842272760640316 0 0.15434633851517643" />
     <axis xyz="0 0 1"/>
       <limit effort="0.0" lower="-3.14159" upper="3.14159" velocity="0.0"/>
    </joint>
    <joint name="Start_Link4" type="revolute">
       <parent link="Start"/>
       <child  link="Link4"/>
       <origin rpy="0 0 0" xyz="0 0 0.5" />
     <axis xyz="0 0 1"/>
       <limit effort="0.0" lower="-3.14159" upper="3.14159" velocity="0.0"/>
    </joint>
</robot>