<robot name = "robot">
    <link name="Start">
        <inertial>
            <origin xyz="0 0 0" rpy="0 0 0"/>
            <mass value="1" />
            <inertia ixx="100" ixy="0" ixz="0" iyy="100" iyz="0" izz="100" />
        </inertial>
        <visual>
            <origin xyz="0 0 0" rpy="0 0 0"/>
            <geometry>
                <box size="1 1 1" />
            </geometry>
            <material name="Green">
                <color rgba="0 1.0 0 1.0"/>
            </material>
        </visual>
        <collision>
            <origin xyz="0 0 0" rpy="0 0 0"/>
            <geometry>
                <box size="1 1 1" />
            </geometry>
        </collision>
    </link>
    <joint name="Start_Link0" type="revolute">
       <parent link="Start"/>
       <child  link="Link0"/>
       <origin rpy="0 0 0" xyz="0 0 -0.5" />
     <axis xyz="0 0 1"/>
       <limit effort="0.0" lower="-3.14159" upper="3.14159" velocity="0.0"/>
    </joint>
    <link name="Link0">
        <inertial>
            <origin xyz="0 0 -0.9389769205678328" rpy="0 0 0"/>
            <mass value="1" />
            <inertia ixx="100" ixy="0" ixz="0" iyy="100" iyz="0" izz="100" />
        </inertial>
        <visual>
            <origin xyz="0 0 -0.9389769205678328" rpy="0 0 0"/>
            <geometry>
                <box size="1.3522836435536805 0.7020100655028527 1.8779538411356655" />
            </geometry>
            <material name="Blue">
                <color rgba="0 0 1.0 1.0"/>
            </material>
        </visual>
        <collision>
            <origin xyz="0 0 -0.9389769205678328" rpy="0 0 0"/>
            <geometry>
                <box size="1.3522836435536805 0.7020100655028527 1.8779538411356655" />
            </geometry>
        </collision>
    </link>
    <joint name="Start_Link1" type="revolute">
       <parent link="Start"/>
       <child  link="Link1"/>
       <origin rpy="0 0 0" xyz="0.5 0 0" />
     <axis xyz="1 0 0"/>
       <limit effort="0.0" lower="-3.14159" upper="3.14159" velocity="0.0"/>
    </joint>
    <link name="Link1">
        <inertial>
            <origin xyz="0.628776065772665 0 0" rpy="0 0 0"/>
            <mass value="1" />
            <inertia ixx="100" ixy="0" ixz="0" iyy="100" iyz="0" izz="100" />
        </inertial>
        <visual>
            <origin xyz="0.628776065772665 0 0" rpy="0 0 0"/>
            <geometry>
                <box size="1.25755213154533 1.3520501386095465 1.0865469026877672" />
            </geometry>
            <material name="Blue">
                <color rgba="0 0 1.0 1.0"/>
            </material>
        </visual>
        <collision>
            <origin xyz="0.628776065772665 0 0" rpy="0 0 0"/>
            <geometry>
                <box size="1.25755213154533 1.3520501386095465 1.0865469026877672" />
            </geometry>
        </collision>
    </link>
    <joint name="Start_Link2" type="revolute">
       <parent link="Start"/>
       <child  link="Link2"/>
       <origin rpy="0 0 0" xyz="-0.5 0 0" />
     <axis xyz="1 0 0"/>
       <limit effort="0.0" lower="-3.14159" upper="3.14159" velocity="0.0"/>
    </joint>
    <link name="Link2">
        <inertial>
            <origin xyz="-0.3534043830995476 0 0" rpy="0 0 0"/>
            <mass value="1" />
            <inertia ixx="100" ixy="0" ixz="0" iyy="100" iyz="0" izz="100" />
        </inertial>
        <visual>
            <origin xyz="-0.3534043830995476 0 0" rpy="0 0 0"/>
            <geometry>
                <box size="0.7068087661990952 1.6659620741558119 1.29016888932811" />
            </geometry>
            <material name="Green">
                <color rgba="0 1.0 0 1.0"/>
            </material>
        </visual>
        <collision>
            <origin xyz="-0.3534043830995476 0 0" rpy="0 0 0"/>
            <geometry>
                <box size="0.7068087661990952 1.6659620741558119 1.29016888932811" />
            </geometry>
        </collision>
    </link>
    <joint name="Link0_Link3" type="revolute">
       <parent link="Link0"/>
       <child  link="Link3"/>
       <origin rpy="0 0 0" xyz="0.6761418217768402 0 -0.9389769205678328" />
     <axis xyz="1 0 0"/>
       <limit effort="0.0" lower="-3.14159" upper="3.14159" velocity="0.0"/>
    </joint>
    <link name="Link3">
        <inertial>
            <origin xyz="0.9904697129862646 0 0" rpy="0 0 0"/>
            <mass value="1" />
            <inertia ixx="100" ixy="0" ixz="0" iyy="100" iyz="0" izz="100" />
        </inertial>
        <visual>
            <origin xyz="0.9904697129862646 0 0" rpy="0 0 0"/>
            <geometry>
                <box size="1.9809394259725293 0.5235508826385595 0.7454209549057358" />
            </geometry>
            <material name="Green">
                <color rgba="0 1.0 0 1.0"/>
            </material>
        </visual>
        <collision>
            <origin xyz="0.9904697129862646 0 0" rpy="0 0 0"/>
            <geometry>
                <box size="1.9809394259725293 0.5235508826385595 0.7454209549057358" />
            </geometry>
        </collision>
    </link>
    <joint name="Start_Link4" type="revolute">
       <parent link="Start"/>
       <child  link="Link4"/>
       <origin rpy="0 0 0" xyz="0 0 0.5" />
     <axis xyz="0 0 1"/>
       <limit effort="0.0" lower="-3.14159" upper="3.14159" velocity="0.0"/>
    </joint>
    <link name="Link4">
        <inertial>
            <origin xyz="0 0 0.949543925357934" rpy="0 0 0"/>
            <mass value="1" />
            <inertia ixx="100" ixy="0" ixz="0" iyy="100" iyz="0" izz="100" />
        </inertial>
        <visual>
            <origin xyz="0 0 0.949543925357934" rpy="0 0 0"/>
            <geometry>
                <box size="0.21435040420542323 1.5043385163451006 1.899087850715868" />
            </geometry>
            <material name="Green">
                <color rgba="0 1.0 0 1.0"/>
            </material>
        </visual>
        <collision>
            <origin xyz="0 0 0.949543925357934" rpy="0 0 0"/>
            <geometry>
                <box size="0.21435040420542323 1.5043385163451006 1.899087850715868" />
            </geometry>
        </collision>
    </link>
</robot>