<robot name = "robot">
    <link name="Start">
        <inertial>
            <origin xyz="0 0 0" rpy="0 0 0"/>
            <mass value="1" />
            <inertia ixx="100" ixy="0" ixz="0" iyy="100" iyz="0" izz="100" />
        </inertial>
        <visual>
            <origin xyz="0 0 0" rpy="0 0 0"/>
            <geometry>
                <box size="0.4072461629408468 0.20737036082466168 0.5358010974792662" />
            </geometry>
            <material name="Blue">
                <color rgba="0 0 1.0 1.0"/>
            </material>
        </visual>
        <collision>
            <origin xyz="0 0 0" rpy="0 0 0"/>
            <geometry>
                <box size="0.4072461629408468 0.20737036082466168 0.5358010974792662" />
            </geometry>
        </collision>
    </link>
    <link name="Link1">
        <inertial>
            <origin xyz="0 0.6537155349923718 0" rpy="0 0 0"/>
            <mass value="1" />
            <inertia ixx="100" ixy="0" ixz="0" iyy="100" iyz="0" izz="100" />
        </inertial>
        <visual>
            <origin xyz="0 0.6537155349923718 0" rpy="0 0 0"/>
            <geometry>
                <box size="0.8195618099662305 0.631098298415315 0.33586644072081545" />
            </geometry>
            <material name="Blue">
                <color rgba="0 0 1.0 1.0"/>
            </material>
        </visual>
        <collision>
            <origin xyz="0 0.6537155349923718 0" rpy="0 0 0"/>
            <geometry>
                <box size="0.8195618099662305 0.631098298415315 0.33586644072081545" />
            </geometry>
        </collision>
    </link>
    <link name="Link4">
        <inertial>
            <origin xyz="0.6369001003612935 0 0" rpy="0 0 0"/>
            <mass value="1" />
            <inertia ixx="100" ixy="0" ixz="0" iyy="100" iyz="0" izz="100" />
        </inertial>
        <visual>
            <origin xyz="0.6369001003612935 0 0" rpy="0 0 0"/>
            <geometry>
                <box size="1.0968334560174986 1.036130644664862 0.363723775722401" />
            </geometry>
            <material name="Blue">
                <color rgba="0 0 1.0 1.0"/>
            </material>
        </visual>
        <collision>
            <origin xyz="0.6369001003612935 0 0" rpy="0 0 0"/>
            <geometry>
                <box size="1.0968334560174986 1.036130644664862 0.363723775722401" />
            </geometry>
        </collision>
    </link>
    <link name="Link5">
        <inertial>
            <origin xyz="0 0 -0.6356477576861248" rpy="0 0 0"/>
            <mass value="1" />
            <inertia ixx="100" ixy="0" ixz="0" iyy="100" iyz="0" izz="100" />
        </inertial>
        <visual>
            <origin xyz="0 0 -0.6356477576861248" rpy="0 0 0"/>
            <geometry>
                <box size="0.24320944350445287 1.1064624483843104 0.5918018792366904" />
            </geometry>
            <material name="Blue">
                <color rgba="0 0 1.0 1.0"/>
            </material>
        </visual>
        <collision>
            <origin xyz="0 0 -0.6356477576861248" rpy="0 0 0"/>
            <geometry>
                <box size="0.24320944350445287 1.1064624483843104 0.5918018792366904" />
            </geometry>
        </collision>
    </link>
    <link name="Link7">
        <inertial>
            <origin xyz="0 0 -0.15844481973466346" rpy="0 0 0"/>
            <mass value="1" />
            <inertia ixx="100" ixy="0" ixz="0" iyy="100" iyz="0" izz="100" />
        </inertial>
        <visual>
            <origin xyz="0 0 -0.15844481973466346" rpy="0 0 0"/>
            <geometry>
                <box size="0.8220359606646293 1.7310506983525284 0.378393924663755" />
            </geometry>
            <material name="Blue">
                <color rgba="0 0 1.0 1.0"/>
            </material>
        </visual>
        <collision>
            <origin xyz="0 0 -0.15844481973466346" rpy="0 0 0"/>
            <geometry>
                <box size="0.8220359606646293 1.7310506983525284 0.378393924663755" />
            </geometry>
        </collision>
    </link>
    <link name="Link8">
        <inertial>
            <origin xyz="-0.32061517159504144 0 0" rpy="0 0 0"/>
            <mass value="1" />
            <inertia ixx="100" ixy="0" ixz="0" iyy="100" iyz="0" izz="100" />
        </inertial>
        <visual>
            <origin xyz="-0.32061517159504144 0 0" rpy="0 0 0"/>
            <geometry>
                <box size="0.6412303431900829 1.8916151181468395 1.6858931789126474" />
            </geometry>
            <material name="Blue">
                <color rgba="0 0 1.0 1.0"/>
            </material>
        </visual>
        <collision>
            <origin xyz="-0.32061517159504144 0 0" rpy="0 0 0"/>
            <geometry>
                <box size="0.6412303431900829 1.8916151181468395 1.6858931789126474" />
            </geometry>
        </collision>
    </link>
    <link name="Link9">
        <inertial>
            <origin xyz="0 0.5435105835089674 0" rpy="0 0 0"/>
            <mass value="1" />
            <inertia ixx="100" ixy="0" ixz="0" iyy="100" iyz="0" izz="100" />
        </inertial>
        <visual>
            <origin xyz="0 0.5435105835089674 0" rpy="0 0 0"/>
            <geometry>
                <box size="1.1296655083400573 1.0870211670179348 1.4657262546478544" />
            </geometry>
            <material name="Blue">
                <color rgba="0 0 1.0 1.0"/>
            </material>
        </visual>
        <collision>
            <origin xyz="0 0.5435105835089674 0" rpy="0 0 0"/>
            <geometry>
                <box size="1.1296655083400573 1.0870211670179348 1.4657262546478544" />
            </geometry>
        </collision>
    </link>
    <link name="Link10">
        <inertial>
            <origin xyz="0 0 -0.20507737983330585" rpy="0 0 0"/>
            <mass value="1" />
            <inertia ixx="100" ixy="0" ixz="0" iyy="100" iyz="0" izz="100" />
        </inertial>
        <visual>
            <origin xyz="0 0 -0.20507737983330585" rpy="0 0 0"/>
            <geometry>
                <box size="0.21162683714375616 1.925787767048253 0.4101547596666117" />
            </geometry>
            <material name="Blue">
                <color rgba="0 0 1.0 1.0"/>
            </material>
        </visual>
        <collision>
            <origin xyz="0 0 -0.20507737983330585" rpy="0 0 0"/>
            <geometry>
                <box size="0.21162683714375616 1.925787767048253 0.4101547596666117" />
            </geometry>
        </collision>
    </link>
    <link name="Link11">
        <inertial>
            <origin xyz="0 0 0.661312228812762" rpy="0 0 0"/>
            <mass value="1" />
            <inertia ixx="100" ixy="0" ixz="0" iyy="100" iyz="0" izz="100" />
        </inertial>
        <visual>
            <origin xyz="0 0 0.661312228812762" rpy="0 0 0"/>
            <geometry>
                <box size="0.36233277153224863 1.2018054981420192 1.8583645973320082" />
            </geometry>
            <material name="Green">
                <color rgba="0 1.0 0 1.0"/>
            </material>
        </visual>
        <collision>
            <origin xyz="0 0 0.661312228812762" rpy="0 0 0"/>
            <geometry>
                <box size="0.36233277153224863 1.2018054981420192 1.8583645973320082" />
            </geometry>
        </collision>
    </link>
    <link name="Link12">
        <inertial>
            <origin xyz="0 0.6446938869961327 0" rpy="0 0 0"/>
            <mass value="1" />
            <inertia ixx="100" ixy="0" ixz="0" iyy="100" iyz="0" izz="100" />
        </inertial>
        <visual>
            <origin xyz="0 0.6446938869961327 0" rpy="0 0 0"/>
            <geometry>
                <box size="0.2617846756358126 1.2893877739922655 1.7090822031438384" />
            </geometry>
            <material name="Blue">
                <color rgba="0 0 1.0 1.0"/>
            </material>
        </visual>
        <collision>
            <origin xyz="0 0.6446938869961327 0" rpy="0 0 0"/>
            <geometry>
                <box size="0.2617846756358126 1.2893877739922655 1.7090822031438384" />
            </geometry>
        </collision>
    </link>
    <joint name="Start_Link1" type="revolute">
       <parent link="Start"/>
       <child  link="Link1"/>
       <origin rpy="0 0 0" xyz="0 0.5 0" />
     <axis xyz="0 1 0"/>
       <limit effort="0.0" lower="-3.14159" upper="3.14159" velocity="0.0"/>
    </joint>
    <joint name="Start_Link4" type="revolute">
       <parent link="Start"/>
       <child  link="Link4"/>
       <origin rpy="0 0 0" xyz="0.5 0 0" />
     <axis xyz="1 0 0"/>
       <limit effort="0.0" lower="-3.14159" upper="3.14159" velocity="0.0"/>
    </joint>
    <joint name="Link1_Link5" type="revolute">
       <parent link="Link1"/>
       <child  link="Link5"/>
       <origin rpy="0 0 0" xyz="0 0.6537155349923718 -0.7682136608132016" />
     <axis xyz="0 0 1"/>
       <limit effort="0.0" lower="-3.14159" upper="3.14159" velocity="0.0"/>
    </joint>
    <joint name="Link5_Link7" type="revolute">
       <parent link="Link5"/>
       <child  link="Link7"/>
       <origin rpy="0 0 0" xyz="0 0 -1.2712955153722496" />
     <axis xyz="0 0 1"/>
       <limit effort="0.0" lower="-3.14159" upper="3.14159" velocity="0.0"/>
    </joint>
    <joint name="Link7_Link8" type="revolute">
       <parent link="Link7"/>
       <child  link="Link8"/>
       <origin rpy="0 0 0" xyz="-0.4110179803323146 0 -0.15844481973466346" />
     <axis xyz="1 0 0"/>
       <limit effort="0.0" lower="-3.14159" upper="3.14159" velocity="0.0"/>
    </joint>
    <joint name="Link5_Link9" type="revolute">
       <parent link="Link5"/>
       <child  link="Link9"/>
       <origin rpy="0 0 0" xyz="0 0.1264464186784523 -0.6356477576861248" />
     <axis xyz="0 1 0"/>
       <limit effort="0.0" lower="-3.14159" upper="3.14159" velocity="0.0"/>
    </joint>
    <joint name="Link4_Link10" type="revolute">
       <parent link="Link4"/>
       <child  link="Link10"/>
       <origin rpy="0 0 0" xyz="0.6369001003612935 0 -0.7260566771866842" />
     <axis xyz="0 0 1"/>
       <limit effort="0.0" lower="-3.14159" upper="3.14159" velocity="0.0"/>
    </joint>
    <joint name="Link9_Link11" type="revolute">
       <parent link="Link9"/>
       <child  link="Link11"/>
       <origin rpy="0 0 0" xyz="0 0.5435105835089674 0.7328631273239272" />
     <axis xyz="0 0 1"/>
       <limit effort="0.0" lower="-3.14159" upper="3.14159" velocity="0.0"/>
    </joint>
    <joint name="Link9_Link12" type="revolute">
       <parent link="Link9"/>
       <child  link="Link12"/>
       <origin rpy="0 0 0" xyz="0 1.0870211670179348 0" />
     <axis xyz="0 1 0"/>
       <limit effort="0.0" lower="-3.14159" upper="3.14159" velocity="0.0"/>
    </joint>
</robot>