<robot name = "robot">
    <link name="Start">
        <inertial>
            <origin xyz="0 0 0" rpy="0 0 0"/>
            <mass value="1" />
            <inertia ixx="100" ixy="0" ixz="0" iyy="100" iyz="0" izz="100" />
        </inertial>
        <visual>
            <origin xyz="0 0 0" rpy="0 0 0"/>
            <geometry>
                <box size="1 1.2517114740512787 1.7682485564601091" />
            </geometry>
            <material name="Blue">
                <color rgba="0 0 1.0 1.0"/>
            </material>
        </visual>
        <collision>
            <origin xyz="0 0 0" rpy="0 0 0"/>
            <geometry>
                <box size="1 1.2517114740512787 1.7682485564601091" />
            </geometry>
        </collision>
    </link>
    <link name="Link1">
        <inertial>
            <origin xyz="0 0 -0.6477489037941998" rpy="0 0 0"/>
            <mass value="1" />
            <inertia ixx="100" ixy="0" ixz="0" iyy="100" iyz="0" izz="100" />
        </inertial>
        <visual>
            <origin xyz="0 0 -0.6477489037941998" rpy="0 0 0"/>
            <geometry>
                <box size="0.4555651290737237 0.545780058326942 0.9827672340295319" />
            </geometry>
            <material name="Blue">
                <color rgba="0 0 1.0 1.0"/>
            </material>
        </visual>
        <collision>
            <origin xyz="0 0 -0.6477489037941998" rpy="0 0 0"/>
            <geometry>
                <box size="0.4555651290737237 0.545780058326942 0.9827672340295319" />
            </geometry>
        </collision>
    </link>
    <link name="Link3">
        <inertial>
            <origin xyz="-0.6665106660786995 0 0" rpy="0 0 0"/>
            <mass value="1" />
            <inertia ixx="100" ixy="0" ixz="0" iyy="100" iyz="0" izz="100" />
        </inertial>
        <visual>
            <origin xyz="-0.6665106660786995 0 0" rpy="0 0 0"/>
            <geometry>
                <box size="1.5292193615665255 0.3009071010940166 0.8765269471150756" />
            </geometry>
            <material name="Blue">
                <color rgba="0 0 1.0 1.0"/>
            </material>
        </visual>
        <collision>
            <origin xyz="-0.6665106660786995 0 0" rpy="0 0 0"/>
            <geometry>
                <box size="1.5292193615665255 0.3009071010940166 0.8765269471150756" />
            </geometry>
        </collision>
    </link>
    <link name="Link8">
        <inertial>
            <origin xyz="0 0 -0.5448554560798962" rpy="0 0 0"/>
            <mass value="1" />
            <inertia ixx="100" ixy="0" ixz="0" iyy="100" iyz="0" izz="100" />
        </inertial>
        <visual>
            <origin xyz="0 0 -0.5448554560798962" rpy="0 0 0"/>
            <geometry>
                <box size="0.6531310897665408 0.7496712331630753 1.0897109121597923" />
            </geometry>
            <material name="Green">
                <color rgba="0 1.0 0 1.0"/>
            </material>
        </visual>
        <collision>
            <origin xyz="0 0 -0.5448554560798962" rpy="0 0 0"/>
            <geometry>
                <box size="0.6531310897665408 0.7496712331630753 1.0897109121597923" />
            </geometry>
        </collision>
    </link>
    <link name="Link11">
        <inertial>
            <origin xyz="-0.8873453508111809 0 0" rpy="0 0 0"/>
            <mass value="1" />
            <inertia ixx="100" ixy="0" ixz="0" iyy="100" iyz="0" izz="100" />
        </inertial>
        <visual>
            <origin xyz="-0.8873453508111809 0 0" rpy="0 0 0"/>
            <geometry>
                <box size="1.51667324886226 1.9069604563434042 1.9787172437053806" />
            </geometry>
            <material name="Blue">
                <color rgba="0 0 1.0 1.0"/>
            </material>
        </visual>
        <collision>
            <origin xyz="-0.8873453508111809 0 0" rpy="0 0 0"/>
            <geometry>
                <box size="1.51667324886226 1.9069604563434042 1.9787172437053806" />
            </geometry>
        </collision>
    </link>
    <link name="Link12">
        <inertial>
            <origin xyz="0 0 -0.131758553623236" rpy="0 0 0"/>
            <mass value="1" />
            <inertia ixx="100" ixy="0" ixz="0" iyy="100" iyz="0" izz="100" />
        </inertial>
        <visual>
            <origin xyz="0 0 -0.131758553623236" rpy="0 0 0"/>
            <geometry>
                <box size="1.3938803394688144 1.9033927180960768 0.263517107246472" />
            </geometry>
            <material name="Blue">
                <color rgba="0 0 1.0 1.0"/>
            </material>
        </visual>
        <collision>
            <origin xyz="0 0 -0.131758553623236" rpy="0 0 0"/>
            <geometry>
                <box size="1.3938803394688144 1.9033927180960768 0.263517107246472" />
            </geometry>
        </collision>
    </link>
    <link name="Link13">
        <inertial>
            <origin xyz="0 0.7616612993159586 0" rpy="0 0 0"/>
            <mass value="1" />
            <inertia ixx="100" ixy="0" ixz="0" iyy="100" iyz="0" izz="100" />
        </inertial>
        <visual>
            <origin xyz="0 0.7616612993159586 0" rpy="0 0 0"/>
            <geometry>
                <box size="0.8297713251575312 1.5233225986319172 1.8868539590433133" />
            </geometry>
            <material name="Green">
                <color rgba="0 1.0 0 1.0"/>
            </material>
        </visual>
        <collision>
            <origin xyz="0 0.7616612993159586 0" rpy="0 0 0"/>
            <geometry>
                <box size="0.8297713251575312 1.5233225986319172 1.8868539590433133" />
            </geometry>
        </collision>
    </link>
    <joint name="Start_Link1" type="revolute">
       <parent link="Start"/>
       <child  link="Link1"/>
       <origin rpy="0 0 0" xyz="0 0 -0.5" />
     <axis xyz="0 0 1"/>
       <limit effort="0.0" lower="-3.14159" upper="3.14159" velocity="0.0"/>
    </joint>
    <joint name="Link1_Link3" type="revolute">
       <parent link="Link1"/>
       <child  link="Link3"/>
       <origin rpy="0 0 0" xyz="-0.9614913320484879 0 -0.6477489037941998" />
     <axis xyz="1 0 0"/>
       <limit effort="0.0" lower="-3.14159" upper="3.14159" velocity="0.0"/>
    </joint>
    <joint name="Link3_Link8" type="revolute">
       <parent link="Link3"/>
       <child  link="Link8"/>
       <origin rpy="0 0 0" xyz="-0.6665106660786995 0 -0.4382634735575378" />
     <axis xyz="0 0 1"/>
       <limit effort="0.0" lower="-3.14159" upper="3.14159" velocity="0.0"/>
    </joint>
    <joint name="Link8_Link11" type="revolute">
       <parent link="Link8"/>
       <child  link="Link11"/>
       <origin rpy="0 0 0" xyz="-0.22420451946990472 0 -0.5448554560798962" />
     <axis xyz="1 0 0"/>
       <limit effort="0.0" lower="-3.14159" upper="3.14159" velocity="0.0"/>
    </joint>
    <joint name="Link11_Link12" type="revolute">
       <parent link="Link11"/>
       <child  link="Link12"/>
       <origin rpy="0 0 0" xyz="-0.8873453508111809 0 -0.9893586218526903" />
     <axis xyz="0 0 1"/>
       <limit effort="0.0" lower="-3.14159" upper="3.14159" velocity="0.0"/>
    </joint>
    <joint name="Link12_Link13" type="revolute">
       <parent link="Link12"/>
       <child  link="Link13"/>
       <origin rpy="0 0 0" xyz="0 0.45133129239577185 -0.131758553623236" />
     <axis xyz="0 1 0"/>
       <limit effort="0.0" lower="-3.14159" upper="3.14159" velocity="0.0"/>
    </joint>
</robot>