<robot name = "robot">
    <link name="Start">
        <inertial>
            <origin xyz="0 0 0" rpy="0 0 0"/>
            <mass value="1" />
            <inertia ixx="100" ixy="0" ixz="0" iyy="100" iyz="0" izz="100" />
        </inertial>
        <visual>
            <origin xyz="0 0 0" rpy="0 0 0"/>
            <geometry>
                <box size="0.24322455698374054 1.6346418111016674 0.4866149547842021" />
            </geometry>
            <material name="Blue">
                <color rgba="0 0 1.0 1.0"/>
            </material>
        </visual>
        <collision>
            <origin xyz="0 0 0" rpy="0 0 0"/>
            <geometry>
                <box size="0.24322455698374054 1.6346418111016674 0.4866149547842021" />
            </geometry>
        </collision>
    </link>
    <link name="Link1">
        <inertial>
            <origin xyz="0 0 -0.9466526402334704" rpy="0 0 0"/>
            <mass value="1" />
            <inertia ixx="100" ixy="0" ixz="0" iyy="100" iyz="0" izz="100" />
        </inertial>
        <visual>
            <origin xyz="0 0 -0.9466526402334704" rpy="0 0 0"/>
            <geometry>
                <box size="0.5051932817765773 1.6697583581232633 1.4710355985099726" />
            </geometry>
            <material name="Blue">
                <color rgba="0 0 1.0 1.0"/>
            </material>
        </visual>
        <collision>
            <origin xyz="0 0 -0.9466526402334704" rpy="0 0 0"/>
            <geometry>
                <box size="0.5051932817765773 1.6697583581232633 1.4710355985099726" />
            </geometry>
        </collision>
    </link>
    <link name="Link7">
        <inertial>
            <origin xyz="0 0 -0.42982932249694195" rpy="0 0 0"/>
            <mass value="1" />
            <inertia ixx="100" ixy="0" ixz="0" iyy="100" iyz="0" izz="100" />
        </inertial>
        <visual>
            <origin xyz="0 0 -0.42982932249694195" rpy="0 0 0"/>
            <geometry>
                <box size="1.3420435313026142 0.29102468731912184 0.272029758792359" />
            </geometry>
            <material name="Blue">
                <color rgba="0 0 1.0 1.0"/>
            </material>
        </visual>
        <collision>
            <origin xyz="0 0 -0.42982932249694195" rpy="0 0 0"/>
            <geometry>
                <box size="1.3420435313026142 0.29102468731912184 0.272029758792359" />
            </geometry>
        </collision>
    </link>
    <link name="Link8">
        <inertial>
            <origin xyz="-0.5263259078382424 0 0" rpy="0 0 0"/>
            <mass value="1" />
            <inertia ixx="100" ixy="0" ixz="0" iyy="100" iyz="0" izz="100" />
        </inertial>
        <visual>
            <origin xyz="-0.5263259078382424 0 0" rpy="0 0 0"/>
            <geometry>
                <box size="0.536527019739875 1.0674329514740597 1.0960684779949308" />
            </geometry>
            <material name="Blue">
                <color rgba="0 0 1.0 1.0"/>
            </material>
        </visual>
        <collision>
            <origin xyz="-0.5263259078382424 0 0" rpy="0 0 0"/>
            <geometry>
                <box size="0.536527019739875 1.0674329514740597 1.0960684779949308" />
            </geometry>
        </collision>
    </link>
    <link name="Link11">
        <inertial>
            <origin xyz="0 0 -0.3933455782336682" rpy="0 0 0"/>
            <mass value="1" />
            <inertia ixx="100" ixy="0" ixz="0" iyy="100" iyz="0" izz="100" />
        </inertial>
        <visual>
            <origin xyz="0 0 -0.3933455782336682" rpy="0 0 0"/>
            <geometry>
                <box size="1.9955816800820856 0.7799202493335309 0.2959647558991605" />
            </geometry>
            <material name="Blue">
                <color rgba="0 0 1.0 1.0"/>
            </material>
        </visual>
        <collision>
            <origin xyz="0 0 -0.3933455782336682" rpy="0 0 0"/>
            <geometry>
                <box size="1.9955816800820856 0.7799202493335309 0.2959647558991605" />
            </geometry>
        </collision>
    </link>
    <link name="Link12">
        <inertial>
            <origin xyz="0 -0.7559317910251833 0" rpy="0 0 0"/>
            <mass value="1" />
            <inertia ixx="100" ixy="0" ixz="0" iyy="100" iyz="0" izz="100" />
        </inertial>
        <visual>
            <origin xyz="0 -0.7559317910251833 0" rpy="0 0 0"/>
            <geometry>
                <box size="1.2260269948038685 1.5118635820503665 1.1276571913385598" />
            </geometry>
            <material name="Blue">
                <color rgba="0 0 1.0 1.0"/>
            </material>
        </visual>
        <collision>
            <origin xyz="0 -0.7559317910251833 0" rpy="0 0 0"/>
            <geometry>
                <box size="1.2260269948038685 1.5118635820503665 1.1276571913385598" />
            </geometry>
        </collision>
    </link>
    <link name="Link13">
        <inertial>
            <origin xyz="0.2752868839907259 0 0" rpy="0 0 0"/>
            <mass value="1" />
            <inertia ixx="100" ixy="0" ixz="0" iyy="100" iyz="0" izz="100" />
        </inertial>
        <visual>
            <origin xyz="0.2752868839907259 0 0" rpy="0 0 0"/>
            <geometry>
                <box size="0.5505737679814517 0.6205013747342573 1.8835138273579326" />
            </geometry>
            <material name="Blue">
                <color rgba="0 0 1.0 1.0"/>
            </material>
        </visual>
        <collision>
            <origin xyz="0.2752868839907259 0 0" rpy="0 0 0"/>
            <geometry>
                <box size="0.5505737679814517 0.6205013747342573 1.8835138273579326" />
            </geometry>
        </collision>
    </link>
    <link name="Link14">
        <inertial>
            <origin xyz="-0.7108667808616056 0 0" rpy="0 0 0"/>
            <mass value="1" />
            <inertia ixx="100" ixy="0" ixz="0" iyy="100" iyz="0" izz="100" />
        </inertial>
        <visual>
            <origin xyz="-0.7108667808616056 0 0" rpy="0 0 0"/>
            <geometry>
                <box size="1.4217335617232112 0.2889453398609028 1.8452137650778029" />
            </geometry>
            <material name="Blue">
                <color rgba="0 0 1.0 1.0"/>
            </material>
        </visual>
        <collision>
            <origin xyz="-0.7108667808616056 0 0" rpy="0 0 0"/>
            <geometry>
                <box size="1.4217335617232112 0.2889453398609028 1.8452137650778029" />
            </geometry>
        </collision>
    </link>
    <link name="Link15">
        <inertial>
            <origin xyz="0 -0.6658920722546477 0" rpy="0 0 0"/>
            <mass value="1" />
            <inertia ixx="100" ixy="0" ixz="0" iyy="100" iyz="0" izz="100" />
        </inertial>
        <visual>
            <origin xyz="0 -0.6658920722546477 0" rpy="0 0 0"/>
            <geometry>
                <box size="1.0317563896250581 1.0239271852438236 0.20888369045581817" />
            </geometry>
            <material name="Blue">
                <color rgba="0 0 1.0 1.0"/>
            </material>
        </visual>
        <collision>
            <origin xyz="0 -0.6658920722546477 0" rpy="0 0 0"/>
            <geometry>
                <box size="1.0317563896250581 1.0239271852438236 0.20888369045581817" />
            </geometry>
        </collision>
    </link>
    <link name="Link16">
        <inertial>
            <origin xyz="0 -0.9234414505750834 0" rpy="0 0 0"/>
            <mass value="1" />
            <inertia ixx="100" ixy="0" ixz="0" iyy="100" iyz="0" izz="100" />
        </inertial>
        <visual>
            <origin xyz="0 -0.9234414505750834 0" rpy="0 0 0"/>
            <geometry>
                <box size="1.201207294843451 1.8468829011501668 1.2720854868041283" />
            </geometry>
            <material name="Blue">
                <color rgba="0 0 1.0 1.0"/>
            </material>
        </visual>
        <collision>
            <origin xyz="0 -0.9234414505750834 0" rpy="0 0 0"/>
            <geometry>
                <box size="1.201207294843451 1.8468829011501668 1.2720854868041283" />
            </geometry>
        </collision>
    </link>
    <joint name="Start_Link1" type="revolute">
       <parent link="Start"/>
       <child  link="Link1"/>
       <origin rpy="0 0 0" xyz="0 0 -0.5" />
     <axis xyz="0 0 1"/>
       <limit effort="0.0" lower="-3.14159" upper="3.14159" velocity="0.0"/>
    </joint>
    <joint name="Link1_Link7" type="revolute">
       <parent link="Link1"/>
       <child  link="Link7"/>
       <origin rpy="0 0 0" xyz="0 0 -1.8933052804669408" />
     <axis xyz="0 0 1"/>
       <limit effort="0.0" lower="-3.14159" upper="3.14159" velocity="0.0"/>
    </joint>
    <joint name="Link7_Link8" type="revolute">
       <parent link="Link7"/>
       <child  link="Link8"/>
       <origin rpy="0 0 0" xyz="-0.6710217656513071 0 -0.42982932249694195" />
     <axis xyz="1 0 0"/>
       <limit effort="0.0" lower="-3.14159" upper="3.14159" velocity="0.0"/>
    </joint>
    <joint name="Link8_Link11" type="revolute">
       <parent link="Link8"/>
       <child  link="Link11"/>
       <origin rpy="0 0 0" xyz="-0.5263259078382424 0 -0.5777164242454361" />
     <axis xyz="0 0 1"/>
       <limit effort="0.0" lower="-3.14159" upper="3.14159" velocity="0.0"/>
    </joint>
    <joint name="Start_Link12" type="revolute">
       <parent link="Start"/>
       <child  link="Link12"/>
       <origin rpy="0 0 0" xyz="0 -0.5 0" />
     <axis xyz="0 1 0"/>
       <limit effort="0.0" lower="-3.14159" upper="3.14159" velocity="0.0"/>
    </joint>
    <joint name="Link1_Link13" type="revolute">
       <parent link="Link1"/>
       <child  link="Link13"/>
       <origin rpy="0 0 0" xyz="0.37311557557512576 0 -0.9466526402334704" />
     <axis xyz="1 0 0"/>
       <limit effort="0.0" lower="-3.14159" upper="3.14159" velocity="0.0"/>
    </joint>
    <joint name="Link11_Link14" type="revolute">
       <parent link="Link11"/>
       <child  link="Link14"/>
       <origin rpy="0 0 0" xyz="-0.43035685715307714 0 -0.3933455782336682" />
     <axis xyz="1 0 0"/>
       <limit effort="0.0" lower="-3.14159" upper="3.14159" velocity="0.0"/>
    </joint>
    <joint name="Link13_Link15" type="revolute">
       <parent link="Link13"/>
       <child  link="Link15"/>
       <origin rpy="0 0 0" xyz="0.2752868839907259 -0.31025068736712863 0" />
     <axis xyz="0 1 0"/>
       <limit effort="0.0" lower="-3.14159" upper="3.14159" velocity="0.0"/>
    </joint>
    <joint name="Link11_Link16" type="revolute">
       <parent link="Link11"/>
       <child  link="Link16"/>
       <origin rpy="0 0 0" xyz="0 -0.781132132580755 -0.3933455782336682" />
     <axis xyz="0 1 0"/>
       <limit effort="0.0" lower="-3.14159" upper="3.14159" velocity="0.0"/>
    </joint>
</robot>