<robot name = "robot">
    <link name="Start">
        <inertial>
            <origin xyz="0 0 0" rpy="0 0 0"/>
            <mass value="1" />
            <inertia ixx="100" ixy="0" ixz="0" iyy="100" iyz="0" izz="100" />
        </inertial>
        <visual>
            <origin xyz="0 0 0" rpy="0 0 0"/>
            <geometry>
                <box size="0.28218463215756917 0.24607999657528143 0.4615697289091794" />
            </geometry>
            <material name="Blue">
                <color rgba="0 0 1.0 1.0"/>
            </material>
        </visual>
        <collision>
            <origin xyz="0 0 0" rpy="0 0 0"/>
            <geometry>
                <box size="0.28218463215756917 0.24607999657528143 0.4615697289091794" />
            </geometry>
        </collision>
    </link>
    <link name="Link1">
        <inertial>
            <origin xyz="0 0 -0.645523913658748" rpy="0 0 0"/>
            <mass value="1" />
            <inertia ixx="100" ixy="0" ixz="0" iyy="100" iyz="0" izz="100" />
        </inertial>
        <visual>
            <origin xyz="0 0 -0.645523913658748" rpy="0 0 0"/>
            <geometry>
                <box size="0.45165040072113244 0.5292297719662851 0.276858881679683" />
            </geometry>
            <material name="Blue">
                <color rgba="0 0 1.0 1.0"/>
            </material>
        </visual>
        <collision>
            <origin xyz="0 0 -0.645523913658748" rpy="0 0 0"/>
            <geometry>
                <box size="0.45165040072113244 0.5292297719662851 0.276858881679683" />
            </geometry>
        </collision>
    </link>
    <link name="Link2">
        <inertial>
            <origin xyz="0.9193563997653486 0 0" rpy="0 0 0"/>
            <mass value="1" />
            <inertia ixx="100" ixy="0" ixz="0" iyy="100" iyz="0" izz="100" />
        </inertial>
        <visual>
            <origin xyz="0.9193563997653486 0 0" rpy="0 0 0"/>
            <geometry>
                <box size="0.4013771279650117 1.9750957637091398 1.2706438963375202" />
            </geometry>
            <material name="Blue">
                <color rgba="0 0 1.0 1.0"/>
            </material>
        </visual>
        <collision>
            <origin xyz="0.9193563997653486 0 0" rpy="0 0 0"/>
            <geometry>
                <box size="0.4013771279650117 1.9750957637091398 1.2706438963375202" />
            </geometry>
        </collision>
    </link>
    <link name="Link3">
        <inertial>
            <origin xyz="0 0 0.27614424925627523" rpy="0 0 0"/>
            <mass value="1" />
            <inertia ixx="100" ixy="0" ixz="0" iyy="100" iyz="0" izz="100" />
        </inertial>
        <visual>
            <origin xyz="0 0 0.27614424925627523" rpy="0 0 0"/>
            <geometry>
                <box size="0.3579684726049243 1.0665208949819291 0.5522884985125505" />
            </geometry>
            <material name="Blue">
                <color rgba="0 0 1.0 1.0"/>
            </material>
        </visual>
        <collision>
            <origin xyz="0 0 0.27614424925627523" rpy="0 0 0"/>
            <geometry>
                <box size="0.3579684726049243 1.0665208949819291 0.5522884985125505" />
            </geometry>
        </collision>
    </link>
    <link name="Link6">
        <inertial>
            <origin xyz="0 0.41738761101711563 0" rpy="0 0 0"/>
            <mass value="1" />
            <inertia ixx="100" ixy="0" ixz="0" iyy="100" iyz="0" izz="100" />
        </inertial>
        <visual>
            <origin xyz="0 0.41738761101711563 0" rpy="0 0 0"/>
            <geometry>
                <box size="1.8737205001774226 1.1031672260554475 1.7513573863636018" />
            </geometry>
            <material name="Blue">
                <color rgba="0 0 1.0 1.0"/>
            </material>
        </visual>
        <collision>
            <origin xyz="0 0.41738761101711563 0" rpy="0 0 0"/>
            <geometry>
                <box size="1.8737205001774226 1.1031672260554475 1.7513573863636018" />
            </geometry>
        </collision>
    </link>
    <link name="Link8">
        <inertial>
            <origin xyz="0 0.23611272907532643 0" rpy="0 0 0"/>
            <mass value="1" />
            <inertia ixx="100" ixy="0" ixz="0" iyy="100" iyz="0" izz="100" />
        </inertial>
        <visual>
            <origin xyz="0 0.23611272907532643 0" rpy="0 0 0"/>
            <geometry>
                <box size="1.1992480200020323 0.2710011874274321 1.0307941591156877" />
            </geometry>
            <material name="Blue">
                <color rgba="0 0 1.0 1.0"/>
            </material>
        </visual>
        <collision>
            <origin xyz="0 0.23611272907532643 0" rpy="0 0 0"/>
            <geometry>
                <box size="1.1992480200020323 0.2710011874274321 1.0307941591156877" />
            </geometry>
        </collision>
    </link>
    <link name="Link9">
        <inertial>
            <origin xyz="0 0.6757860057502039 0" rpy="0 0 0"/>
            <mass value="1" />
            <inertia ixx="100" ixy="0" ixz="0" iyy="100" iyz="0" izz="100" />
        </inertial>
        <visual>
            <origin xyz="0 0.6757860057502039 0" rpy="0 0 0"/>
            <geometry>
                <box size="0.750837675651864 1.2888447585158027 1.694271051701583" />
            </geometry>
            <material name="Blue">
                <color rgba="0 0 1.0 1.0"/>
            </material>
        </visual>
        <collision>
            <origin xyz="0 0.6757860057502039 0" rpy="0 0 0"/>
            <geometry>
                <box size="0.750837675651864 1.2888447585158027 1.694271051701583" />
            </geometry>
        </collision>
    </link>
    <link name="Link12">
        <inertial>
            <origin xyz="0 0 -0.6557805774694881" rpy="0 0 0"/>
            <mass value="1" />
            <inertia ixx="100" ixy="0" ixz="0" iyy="100" iyz="0" izz="100" />
        </inertial>
        <visual>
            <origin xyz="0 0 -0.6557805774694881" rpy="0 0 0"/>
            <geometry>
                <box size="0.5844177683603744 1.7438119828671395 1.3115611549389763" />
            </geometry>
            <material name="Blue">
                <color rgba="0 0 1.0 1.0"/>
            </material>
        </visual>
        <collision>
            <origin xyz="0 0 -0.6557805774694881" rpy="0 0 0"/>
            <geometry>
                <box size="0.5844177683603744 1.7438119828671395 1.3115611549389763" />
            </geometry>
        </collision>
    </link>
    <link name="Link13">
        <inertial>
            <origin xyz="0 0.2182173534044431 0" rpy="0 0 0"/>
            <mass value="1" />
            <inertia ixx="100" ixy="0" ixz="0" iyy="100" iyz="0" izz="100" />
        </inertial>
        <visual>
            <origin xyz="0 0.2182173534044431 0" rpy="0 0 0"/>
            <geometry>
                <box size="0.787086059306257 0.4364347068088862 0.8012496394600881" />
            </geometry>
            <material name="Blue">
                <color rgba="0 0 1.0 1.0"/>
            </material>
        </visual>
        <collision>
            <origin xyz="0 0.2182173534044431 0" rpy="0 0 0"/>
            <geometry>
                <box size="0.787086059306257 0.4364347068088862 0.8012496394600881" />
            </geometry>
        </collision>
    </link>
    <link name="Link14">
        <inertial>
            <origin xyz="0 0.47282342467279836 0" rpy="0 0 0"/>
            <mass value="1" />
            <inertia ixx="100" ixy="0" ixz="0" iyy="100" iyz="0" izz="100" />
        </inertial>
        <visual>
            <origin xyz="0 0.47282342467279836 0" rpy="0 0 0"/>
            <geometry>
                <box size="1.569533156683648 0.9456468493455967 0.9037804502979376" />
            </geometry>
            <material name="Green">
                <color rgba="0 1.0 0 1.0"/>
            </material>
        </visual>
        <collision>
            <origin xyz="0 0.47282342467279836 0" rpy="0 0 0"/>
            <geometry>
                <box size="1.569533156683648 0.9456468493455967 0.9037804502979376" />
            </geometry>
        </collision>
    </link>
    <joint name="Start_Link1" type="revolute">
       <parent link="Start"/>
       <child  link="Link1"/>
       <origin rpy="0 0 0" xyz="0 0 -0.5" />
     <axis xyz="0 0 1"/>
       <limit effort="0.0" lower="-3.14159" upper="3.14159" velocity="0.0"/>
    </joint>
    <joint name="Link1_Link2" type="revolute">
       <parent link="Link1"/>
       <child  link="Link2"/>
       <origin rpy="0 0 0" xyz="0.39305227362569495 0 -0.645523913658748" />
     <axis xyz="1 0 0"/>
       <limit effort="0.0" lower="-3.14159" upper="3.14159" velocity="0.0"/>
    </joint>
    <joint name="Link2_Link3" type="revolute">
       <parent link="Link2"/>
       <child  link="Link3"/>
       <origin rpy="0 0 0" xyz="0.9193563997653486 0 0.6353219481687601" />
     <axis xyz="0 0 1"/>
       <limit effort="0.0" lower="-3.14159" upper="3.14159" velocity="0.0"/>
    </joint>
    <joint name="Link1_Link6" type="revolute">
       <parent link="Link1"/>
       <child  link="Link6"/>
       <origin rpy="0 0 0" xyz="0 0.9760242265090183 -0.645523913658748" />
     <axis xyz="0 1 0"/>
       <limit effort="0.0" lower="-3.14159" upper="3.14159" velocity="0.0"/>
    </joint>
    <joint name="Link6_Link8" type="revolute">
       <parent link="Link6"/>
       <child  link="Link8"/>
       <origin rpy="0 0 0" xyz="0 0.8347752220342313 0" />
     <axis xyz="0 1 0"/>
       <limit effort="0.0" lower="-3.14159" upper="3.14159" velocity="0.0"/>
    </joint>
    <joint name="Link8_Link9" type="revolute">
       <parent link="Link8"/>
       <child  link="Link9"/>
       <origin rpy="0 0 0" xyz="0 0.47222545815065287 0" />
     <axis xyz="0 1 0"/>
       <limit effort="0.0" lower="-3.14159" upper="3.14159" velocity="0.0"/>
    </joint>
    <joint name="Link9_Link12" type="revolute">
       <parent link="Link9"/>
       <child  link="Link12"/>
       <origin rpy="0 0 0" xyz="0 0.6757860057502039 -0.9438536128680531" />
     <axis xyz="0 0 1"/>
       <limit effort="0.0" lower="-3.14159" upper="3.14159" velocity="0.0"/>
    </joint>
    <joint name="Link12_Link13" type="revolute">
       <parent link="Link12"/>
       <child  link="Link13"/>
       <origin rpy="0 0 0" xyz="0 0.7208543839561633 -0.6557805774694881" />
     <axis xyz="0 1 0"/>
       <limit effort="0.0" lower="-3.14159" upper="3.14159" velocity="0.0"/>
    </joint>
    <joint name="Link13_Link14" type="revolute">
       <parent link="Link13"/>
       <child  link="Link14"/>
       <origin rpy="0 0 0" xyz="0 0.4364347068088862 0" />
     <axis xyz="0 1 0"/>
       <limit effort="0.0" lower="-3.14159" upper="3.14159" velocity="0.0"/>
    </joint>
</robot>